Workbook

Sheet Instrucciones
B1: Seguimiento semanal de las Prioridades de los primeros 100 días · SENAMHI
B3: QUÉ ES
B4: Cada dirección actualiza, una vez por semana, el avance de las actividades que SENAMHI comprometió en la Matriz de Prioridades 100 días del Sector Ambiente (MINAM). El dashboard se actualiza solo con lo que se escribe aquí.
B6: DÓNDE ESCRIBIR
B7: Solo en la pestaña Seguimiento , en la fila de su actividad:
B8: • Avance % <fecha> (columnas amarillas): el avance ACUMULADO a esa fecha, de 0 a 100, número entero. No es el avance de la semana: si la semana pasada iban en 20 y avanzaron 10, escriben 30.
B9: • Qué se hizo <fecha>: una o dos líneas con lo realizado en la semana.
B10: • Estado actual: elegir de la lista (Sin iniciar, En proceso, Con riesgo / retraso, Completado, Reprogramado), igual que en la matriz del MINAM.
B11: • Enlace responsable, Link entregable (Drive) y Alertas / riesgos de su fila.
B13: HASTA CUÁNDO
B14: Cada jueves hasta las 17:00. El corte es el viernes y se revisa en la reunión de los viernes.
B16: QUÉ NO TOCAR
... B26: Seguimiento: la única que se edita. · Hitos_RutaElNino: comisiones de la Ruta de Vigilancia El Niño (la actualiza la DMCA). · Calculos, Historial, Resumen: fórmulas, las lee el dashboard. · Config: fechas de referencia.

Sheet Seguimiento
A1: Fila de fechas de corte: no editar | Q1: 46297 | R1: 46304 | T1: 46311 | V1: 46318 | X1: 46325 | Z1: 46332 | AB1: 46339 | AD1: 46346 | AF1: 46353 | AH1: 46360 | AJ1: 46367 | AL1: 46374
A2: ID | B2: Dirección | C2: Nombre corto | D2: Actividad (matriz MINAM) | E2: Producto / Entregable | F2: Unidad de medida | G2: Meta | H2: Línea base | I2: Prioridad (MINAM) | J2: Relacionada con El Niño (propuesta) | K2: Fecha inicio | L2: Fecha límite | M2: Estado actual | N2: Enlace responsable | O2: Link entregable (Drive) | P2: Alertas / riesgos | Q2: Base (matriz MINAM) | R2: Avance % 09/10 | S2: Qué se hizo 09/10 | T2: Avance % 16/10 | U2: Qué se hizo 16/10 | V2: Avance % 23/10 | W2: Qué se hizo 23/10 | X2: Avance % 30/10 | Y2: Qué se hizo 30/10 | Z2: Avance % 06/11 | AA2: Qué se hizo 06/11 | AB2: Avance % 13/11 | AC2: Qué se hizo 13/11 | AD2: Avance % 20/11 | AE2: Qué se hizo 20/11 | AF2: Avance % 27/11 | AG2: Qué se hizo 27/11 | AH2: Avance % 04/12 | AI2: Qué se hizo 04/12 | AJ2: Avance % 11/12 | AK2: Qué se hizo 11/12 | AL2: Avance % 18/12 | AM2: Qué se hizo 18/12
A3: SENAMHI-DHI-01 | B3: DHI | C3: Aforos de caudales en cuencas de Piura y Lima (alerta temprana) | D3: Intensificar aforos para recalibrar y ajustar la curva altura gasto para la generación continua de caudales en tiempo real | E3: Informes técnicos de aforos de caudal | F3: N° informes técnicos | G3: 2 | H3: 6 | I3: Media | J3: No | K3: 46235 | L3: 46296 | M3: En proceso | P3: Eventual falla de equipos de mediciones de caudal | Q3: 15
A4: SENAMHI-DHI-02 | B4: DHI | C4: Pronósticos hidrológicos estacionales | D4: Pronostico hidrológico estacional | E4: Informe técnico mensual del Pronostico hidrológico estacional | F4: N° informes técnicos | G4: 2 | H4: 7 | I4: Media | J4: No | K4: 46235 | L4: 46296 | M4: En proceso | P4: Demora en la implementación del pronóstico estacional de caudales | Q4: 50 | R4: 60 | S4: EJEMPLO (borrar): informe de setiembre emitido
A5: SENAMHI-DHI-03 | B5: DHI | C5: Portal ARES de inundaciones urbanas (Piura y Cusco) | D5: Actualización del portal frente a inundaciones urbanas ARES | E5: Plataforma digital de inundaciones-ARES | F5: Visor de inundaciones pluviales | G5: 1 | H5: 0 | I5: Media | J5: No | K5: 46204 | L5: 46357 | M5: En proceso | P5: Eventual retraso en la producción de plataforma digital por alta demanda en la atención de servicios de OTI | Q5: 30
A6: SENAMHI-DHI-04 | B6: DHI | C6: Plataforma PANDORA en la cuenca del río Madre de Dios | D6: Extensión del producto de pronóstico hidrológico diario PANDORA a la cuenca del río Madre de Dios | E6: Plataforma digital de pronóstico de inundaciones en cuenca Madre de Dios | F6: Visor de pronóstico de inundaciones | G6: 1 | H6: 0 | I6: Media | J6: No | K6: 46204 | L6: 46357 | M6: En proceso | P6: Eventual retraso en la producción de plataforma digital por alta demanda en la atención de servicios de OTI | Q6: 50
A7: SENAMHI-DRD-01 | B7: DRD | C7: Sensores automáticos en estaciones convencionales (vertiente occidental) | D7: Implementación de sensores de precipitación, humedad relativa y temperatura en estaciones convencionales | E7: Modernnización de estaciones | F7: Estación | G7: 27 | H7: 17 | I7: Media | J7: Sí | K7: 46235 | L7: 46336 | M7: En proceso | P7: Eventual demora en la entrega de insumos por los proveedores. | Q7: 50
A8: SENAMHI-DSCA-01 | B8: DSCA | C8: Monitor Integrado de Sequías (ISPI), incluye sequía agrícola | D8: Puesta en operación del Monitor de Sequía Agrícola (V1.0) con acceso público. | E8: Disponibilizar en tiempo real los indices | F8: Plataforma interactiva | G8: 1 | H8: 0 | I8: Media | J8: No | K8: 46254 | L8: 46356 | M8: En proceso | P8: Demora en la implementación de los índices | Q8: 85
A9: SENAMHI-DSCA-02 | B9: DSCA | C9: Equipamiento agrometeorológico de precisión en estaciones MAP | D9: Implementación y puesta en operación de equipamiento agrometeorológico de precisión | E9: 13 nuevos equipamiento agrometeorológicos de precisión en operación. | F9: Estación | G9: 159 | H9: 146 | I9: Media | J9: No | K9: 46254 | L9: 46356 | M9: En proceso | P9: Demora en la instalación de equipos | Q9: 53 | R9: 58 | S9: EJEMPLO (borrar): 2 estaciones instaladas en Cusco
A10: SENAMHI-DSCA-03 | B10: DSCA | C10: Plataforma SORIAN con modelos de alta resolución | D10: Implementar mejoras funcionales y operativas en SORIAN, incorporando y optimizando procesos automatizados para la generación, actualización, procesamiento y visualización de productos de predicción climática en diferentes escalas temporales. | E10: Plataforma SORIAN fortalecida y operativa, con mejoras implementadas en los procesos de generación, procesamiento y visualización de productos climáticos. Informe técnico de implementación y validación de las mejoras realizadas. La actividad se realizará con recursos propios | F10: Sistema / Plataforma fortalecida | G10: 1 | H10: 0 | I10: Alta | J10: Sí | K10: 46235 | L10: 46325 | M10: En proceso | P10: Limitaciones de soporte tecnológico y disponibilidad de personal especializado | Q10: 30
A11: SENAMHI-DMCA-01 | B11: DMCA | C11: Boletines de calidad del aire por incendios forestales en la Amazonía | D11: Generación de información técnica y oportuna mediante la Vigilancia Ambiental Atmosférica en la Amazonía peruana frente a la ocurrencia de incendios forestales en el contexto del Fenómeno El Niño. | E11: Boletín de calidad del aire | F11: Documento | G11: 3 | H11: 0 | I11: Alta | J11: Sí | K11: 46235 | L11: 46336 | M11: En proceso | P11: Insuficiente cobertura de monitoreo de la calidad del aire en la Amazonía peruana, lo que limita la generación de información oportuna para evaluar los impactos de los incendios forestales durante el Fenómeno El Niño. | Q11: 35 | R11: 45 | S11: EJEMPLO (borrar): se instalaron 2 puntos de monitoreo en Loreto
A12: SENAMHI-DMCA-02 | B12: DMCA | C12: Campaña de intercomparación de espectrofotómetros Dobson 2026 | D12: Campaña Regional de Intercomparación de Espectrofotómetros Dobson en América Latina 2026”, a realizarse del 09 al 27 de noviembre de 2026 en la ciudad de Buenos Aires, República Argentina | E12: Certificado de capacitación | F12: Informe | G12: 2 | H12: 0 | I12: Alta | J12: No | K12: 46335 | L12: 46353 | M12: En proceso | P12: Disponibilidad de movilidad para el traslado del Espectrofotómetro Dobson desde el Observatorio de Vigilancia Atmosférica de Marcapomacocha a la Sede Central | Q12: 20
A13: SENAMHI-DMCA-03 | B13: DMCA | C13: Productos de los radares meteorológicos de Piura e Ica | D13: Desarrollo de productos meteorológicos basados en datos de los radares meteorológicos para el fortalecimiento del Sistema de Alerta Temprana. | E13: Visualización web de productos meteorológicos básicos generados a partir de datos de los radares meteorológicos. | F13: Número de imágenes generadas por cada radar (Piura e Ica) | G13: Por cada radar: 288 imágenes/día. | H13: 0 | I13: Alta | J13: No | K13: 46235 | L13: 46255 | M13: Completado | P13: Implementación en la página web del SENAMHI de las imágenes de radar meteorológico de Piura e Ica, permitiendo su visualización para el monitoreo de las condiciones atmosféricas. https://www.senamhi.gob.pe/?p=satelites-radares | Q13: 100
A14: SENAMHI-DMCA-04 | B14: DMCA | C14: Monitor de Sequías del SENAMHI v1 (índices climáticos) | D14: Monitor de Sequías del SENAMHI v1. | E14: Pagina web de consulta sobre el monitoreo de Sequias a nivel nacional con indices. | F14: Pagina WEB | G14: 1 | H14: 0 | I14: Media | J14: No | L14: 46295 | M14: En proceso | P14: Limitaciones tecnológicas para actualizaciones futuras | Q14: 98 | R14: 100 | S14: EJEMPLO (borrar): Monitor de Sequías publicado en la web
A15: SENAMHI-DMCA-05 | B15: DMCA | C15: Ruta de Vigilancia El Niño (difusión en regiones expuestas) | D15: Ruta de Vigilancia El Niño | E15: Reporte de comisiones en las regiones. | F15: Comisiones de servicio. | G15: 1 | H15: 0 | I15: Media | J15: Sí | K15: 46235 | L15: 46357 | M15: En proceso | P15: Cruce de actividades que limiten viaje de comisionados | Q15: 50 | R15: 55 | S15: EJEMPLO (borrar): comisiones a Chiclayo y Tumbes realizadas

Sheet Calculos
A1: ID | B1: Dirección | C1: Nombre corto | D1: Actividad | E1: Producto | F1: Unidad | G1: Meta | H1: Línea base | I1: Prioridad (MINAM) | J1: Relacionada con El Niño | K1: Estado actual | L1: Enlace responsable | M1: Fecha inicio | N1: Fecha límite | O1: Link entregable | P1: Alertas | Q1: Último corte | R1: Avance (%) | S1: Acciones | T1: Día de gestión | U1: Días para el límite | V1: Situación de plazo | W1: Reportó esta semana | X1: Semanas sin reportar | Y1: Hitos cumplidos | Z1: Base (%)
A2: =IF(Seguimiento!A3="","",Seguimiento!A3) | B2: =IF(Seguimiento!A3="","",Seguimiento!B3) | C2: =IF(Seguimiento!A3="","",Seguimiento!C3&"") | D2: =IF(Seguimiento!A3="","",Seguimiento!D3&"") | E2: =IF(Seguimiento!A3="","",Seguimiento!E3&"") | F2: =IF(Seguimiento!A3="","",Seguimiento!F3&"") | G2: =IF(Seguimiento!A3="","",Seguimiento!G3&"") | H2: =IF(Seguimiento!A3="","",Seguimiento!H3&"") | I2: =IF(Seguimiento!A3="","",Seguimiento!I3&"") | J2: =IF(Seguimiento!A3="","",Seguimiento!J3&"") | K2: =IF(Seguimiento!A3="","",Seguimiento!M3&"") | L2: =IF(Seguimiento!A3="","",Seguimiento!N3&"") | M2: =IF(Seguimiento!K3="","",Seguimiento!K3) | N2: =IF(Seguimiento!L3="","",Seguimiento!L3) | O2: =IF(Seguimiento!A3="","",Seguimiento!O3&"") | P2: =IF(Seguimiento!A3="","",Seguimiento!P3&"") | Q2: =IF(A2="","",IFERROR(LOOKUP(2,1/((Seguimiento!$R$1:$AM$1<>"")*(Seguimiento!$R3:$AM3<>"")),Seguimiento!$R$1:$AM$1),"Base")) | R2: =IF(A2="","",IF(ISERROR(LOOKUP(2,1/((Seguimiento!$R$1:$AM$1<>"")*(Seguimiento!$R3:$AM3<>"")),Seguimiento!$R3:$AM3)),IF(Seguimiento!Q3="","",IF(ISNUMBER(Seguimiento!Q3),IF(Seguimiento!Q3<=1,Seguimiento!Q3*100,Seguimiento!Q3),IFERROR(IF(VALUE(SUBSTITUTE(SUBSTITUTE(Seguimiento!Q3,"%",""),",","."))<=1,VALUE(SUBSTITUTE(SUBSTITUTE(Seguimiento!Q3,"%",""),",","."))*100,VALUE(SUBSTITUTE(SUBSTITUTE(Seguimiento!Q3,"%",""),",","."))),""))),IF(ISNUMBER(LOOKUP(2,1/((Seguimiento!$R$1:$AM$1<>"")*(Seguimiento!$R3:$AM3<>"")),Seguimiento!$R3:$AM3)),IF(LOOKUP(2,1/((Seguimiento!$R$1:$AM$1<>"")*(Seguimiento!$R3:$AM3<>"")),Seguimiento!$R3:$AM3)<=1,LOOKUP(2,1/((Seguimiento!$R$1:$AM$1<>"")*(Seguimiento!$R3:$AM3<>"")),Seguimiento!$R3:$AM3)*100,LOOKUP(2,1/((Seguimiento!$R$1:$AM$1<>"")*(Seguimiento!$R3:$AM3<>"")),Seguimiento!$R3:$AM3)),IFERROR(IF(VALUE(SUBSTITUTE(SUBSTITUTE(LOOKUP(2,1/((Seguimiento!$R$1:$AM$1<>"")*(Seguimiento!$R3:$AM3<>"")),Seguimiento!$R3:$AM3),"%",""),",","."))<=1,VALUE(SUBSTITUTE(SUBSTITUTE(LOOKUP(2,1/((Seguimiento!$R$1:$AM$1<>"")*(Seguimiento!$R3:$AM3<>"")),Seguimiento!$R3:$AM3),"%",""),",","."))*100,VALUE(SUBSTITUTE(SUBSTITUTE(LOOKUP(2,1/((Seguimiento!$R$1:$AM$1<>"")*(Seguimiento!$R3:$AM3<>"")),Seguimiento!$R3:$AM3),"%",""),",","."))),"")))) | S2: =IF(OR(A2="",Q2="Base"),"",IFERROR(INDEX(Seguimiento!$R3:$AM3,MATCH(Q2,Seguimiento!$R$1:$AM$1,0)+1)&"","")) | T2: =IF(A2="","",TODAY()-Config!$B$2+1) | U2: =IF(OR(A2="",N2=""),"",N2-TODAY()) | V2: =IF(A2="","",IF(AND(R2<>"",R2>=100),"Completada",IF(N2="","Sin fecha límite",IF(TODAY()>N2,"Fecha límite vencida",IF(AND(M2<>"",TODAY()<M2),"Por iniciar","En plazo"))))) | W2: =IF(A2="","",IF(IFERROR(INDEX(Seguimiento!$R3:$AM3,MATCH(Config!$B$4,Seguimiento!$R$1:$AM$1,0)),"")="","No","Sí")) | X2: =IF(A2="","",COUNTIF(Seguimiento!$R$1:$AM$1,"<="&Config!$B$4)-SUMPRODUCT((Seguimiento!$R$1:$AM$1<>"")*(Seguimiento!$R$1:$AM$1<=Config!$B$4)*(Seguimiento!$R3:$AM3<>""))) | Y2: =IF(ISNUMBER(SEARCH("Ruta de Vigilancia",C2)),COUNTIF(Hitos_RutaElNino!$C$2:$C$200,"Sí")&" / "&COUNTIF(Hitos_RutaElNino!$A$2:$A$200,"<>"),"") | Z2: =IF(A2="","",IF(Seguimiento!Q3="","",IF(ISNUMBER(Seguimiento!Q3),IF(Seguimiento!Q3<=1,Seguimiento!Q3*100,Seguimiento!Q3),IFERROR(IF(VALUE(SUBSTITUTE(SUBSTITUTE(Seguimiento!Q3,"%",""),",","."))<=1,VALUE(SUBSTITUTE(SUBSTITUTE(Seguimiento!Q3,"%",""),",","."))*100,VALUE(SUBSTITUTE(SUBSTITUTE(Seguimiento!Q3,"%",""),",","."))),""))))
A3: =IF(Seguimiento!A4="","",Seguimiento!A4) | B3: =IF(Seguimiento!A4="","",Seguimiento!B4) | C3: =IF(Seguimiento!A4="","",Seguimiento!C4&"") | D3: =IF(Seguimiento!A4="","",Seguimiento!D4&"") | E3: =IF(Seguimiento!A4="","",Seguimiento!E4&"") | F3: =IF(Seguimiento!A4="","",Seguimiento!F4&"") | G3: =IF(Seguimiento!A4="","",Seguimiento!G4&"") | H3: =IF(Seguimiento!A4="","",Seguimiento!H4&"") | I3: =IF(Seguimiento!A4="","",Seguimiento!I4&"") | J3: =IF(Seguimiento!A4="","",Seguimiento!J4&"") | K3: =IF(Seguimiento!A4="","",Seguimiento!M4&"") | L3: =IF(Seguimiento!A4="","",Seguimiento!N4&"") | M3: =IF(Seguimiento!K4="","",Seguimiento!K4) | N3: =IF(Seguimiento!L4="","",Seguimiento!L4) | O3: =IF(Seguimiento!A4="","",Seguimiento!O4&"") | P3: =IF(Seguimiento!A4="","",Seguimiento!P4&"") | Q3: =IF(A3="","",IFERROR(LOOKUP(2,1/((Seguimiento!$R$1:$AM$1<>"")*(Seguimiento!$R4:$AM4<>"")),Seguimiento!$R$1:$AM$1),"Base")) | R3: =IF(A3="","",IF(ISERROR(LOOKUP(2,1/((Seguimiento!$R$1:$AM$1<>"")*(Seguimiento!$R4:$AM4<>"")),Seguimiento!$R4:$AM4)),IF(Seguimiento!Q4="","",IF(ISNUMBER(Seguimiento!Q4),IF(Seguimiento!Q4<=1,Seguimiento!Q4*100,Seguimiento!Q4),IFERROR(IF(VALUE(SUBSTITUTE(SUBSTITUTE(Seguimiento!Q4,"%",""),",","."))<=1,VALUE(SUBSTITUTE(SUBSTITUTE(Seguimiento!Q4,"%",""),",","."))*100,VALUE(SUBSTITUTE(SUBSTITUTE(Seguimiento!Q4,"%",""),",","."))),""))),IF(ISNUMBER(LOOKUP(2,1/((Seguimiento!$R$1:$AM$1<>"")*(Seguimiento!$R4:$AM4<>"")),Seguimiento!$R4:$AM4)),IF(LOOKUP(2,1/((Seguimiento!$R$1:$AM$1<>"")*(Seguimiento!$R4:$AM4<>"")),Seguimiento!$R4:$AM4)<=1,LOOKUP(2,1/((Seguimiento!$R$1:$AM$1<>"")*(Seguimiento!$R4:$AM4<>"")),Seguimiento!$R4:$AM4)*100,LOOKUP(2,1/((Seguimiento!$R$1:$AM$1<>"")*(Seguimiento!$R4:$AM4<>"")),Seguimiento!$R4:$AM4)),IFERROR(IF(VALUE(SUBSTITUTE(SUBSTITUTE(LOOKUP(2,1/((Seguimiento!$R$1:$AM$1<>"")*(Seguimiento!$R4:$AM4<>"")),Seguimiento!$R4:$AM4),"%",""),",","."))<=1,VALUE(SUBSTITUTE(SUBSTITUTE(LOOKUP(2,1/((Seguimiento!$R$1:$AM$1<>"")*(Seguimiento!$R4:$AM4<>"")),Seguimiento!$R4:$AM4),"%",""),",","."))*100,VALUE(SUBSTITUTE(SUBSTITUTE(LOOKUP(2,1/((Seguimiento!$R$1:$AM$1<>"")*(Seguimiento!$R4:$AM4<>"")),Seguimiento!$R4:$AM4),"%",""),",","."))),"")))) | S3: =IF(OR(A3="",Q3="Base"),"",IFERROR(INDEX(Seguimiento!$R4:$AM4,MATCH(Q3,Seguimiento!$R$1:$AM$1,0)+1)&"","")) | T3: =IF(A3="","",TODAY()-Config!$B$2+1) | U3: =IF(OR(A3="",N3=""),"",N3-TODAY()) | V3: =IF(A3="","",IF(AND(R3<>"",R3>=100),"Completada",IF(N3="","Sin fecha límite",IF(TODAY()>N3,"Fecha límite vencida",IF(AND(M3<>"",TODAY()<M3),"Por iniciar","En plazo"))))) | W3: =IF(A3="","",IF(IFERROR(INDEX(Seguimiento!$R4:$AM4,MATCH(Config!$B$4,Seguimiento!$R$1:$AM$1,0)),"")="","No","Sí")) | X3: =IF(A3="","",COUNTIF(Seguimiento!$R$1:$AM$1,"<="&Config!$B$4)-SUMPRODUCT((Seguimiento!$R$1:$AM$1<>"")*(Seguimiento!$R$1:$AM$1<=Config!$B$4)*(Seguimiento!$R4:$AM4<>""))) | Y3: =IF(ISNUMBER(SEARCH("Ruta de Vigilancia",C3)),COUNTIF(Hitos_RutaElNino!$C$2:$C$200,"Sí")&" / "&COUNTIF(Hitos_RutaElNino!$A$2:$A$200,"<>"),"") | Z3: =IF(A3="","",IF(Seguimiento!Q4="","",IF(ISNUMBER(Seguimiento!Q4),IF(Seguimiento!Q4<=1,Seguimiento!Q4*100,Seguimiento!Q4),IFERROR(IF(VALUE(SUBSTITUTE(SUBSTITUTE(Seguimiento!Q4,"%",""),",","."))<=1,VALUE(SUBSTITUTE(SUBSTITUTE(Seguimiento!Q4,"%",""),",","."))*100,VALUE(SUBSTITUTE(SUBSTITUTE(Seguimiento!Q4,"%",""),",","."))),""))))
A4: =IF(Seguimiento!A5="","",Seguimiento!A5) | B4: =IF(Seguimiento!A5="","",Seguimiento!B5) | C4: =IF(Seguimiento!A5="","",Seguimiento!C5&"") | D4: =IF(Seguimiento!A5="","",Seguimiento!D5&"") | E4: =IF(Seguimiento!A5="","",Seguimiento!E5&"") | F4: =IF(Seguimiento!A5="","",Seguimiento!F5&"") | G4: =IF(Seguimiento!A5="","",Seguimiento!G5&"") | H4: =IF(Seguimiento!A5="","",Seguimiento!H5&"") | I4: =IF(Seguimiento!A5="","",Seguimiento!I5&"") | J4: =IF(Seguimiento!A5="","",Seguimiento!J5&"") | K4: =IF(Seguimiento!A5="","",Seguimiento!M5&"") | L4: =IF(Seguimiento!A5="","",Seguimiento!N5&"") | M4: =IF(Seguimiento!K5="","",Seguimiento!K5) | N4: =IF(Seguimiento!L5="","",Seguimiento!L5) | O4: =IF(Seguimiento!A5="","",Seguimiento!O5&"") | P4: =IF(Seguimiento!A5="","",Seguimiento!P5&"") | Q4: =IF(A4="","",IFERROR(LOOKUP(2,1/((Seguimiento!$R$1:$AM$1<>"")*(Seguimiento!$R5:$AM5<>"")),Seguimiento!$R$1:$AM$1),"Base")) | R4: =IF(A4="","",IF(ISERROR(LOOKUP(2,1/((Seguimiento!$R$1:$AM$1<>"")*(Seguimiento!$R5:$AM5<>"")),Seguimiento!$R5:$AM5)),IF(Seguimiento!Q5="","",IF(ISNUMBER(Seguimiento!Q5),IF(Seguimiento!Q5<=1,Seguimiento!Q5*100,Seguimiento!Q5),IFERROR(IF(VALUE(SUBSTITUTE(SUBSTITUTE(Seguimiento!Q5,"%",""),",","."))<=1,VALUE(SUBSTITUTE(SUBSTITUTE(Seguimiento!Q5,"%",""),",","."))*100,VALUE(SUBSTITUTE(SUBSTITUTE(Seguimiento!Q5,"%",""),",","."))),""))),IF(ISNUMBER(LOOKUP(2,1/((Seguimiento!$R$1:$AM$1<>"")*(Seguimiento!$R5:$AM5<>"")),Seguimiento!$R5:$AM5)),IF(LOOKUP(2,1/((Seguimiento!$R$1:$AM$1<>"")*(Seguimiento!$R5:$AM5<>"")),Seguimiento!$R5:$AM5)<=1,LOOKUP(2,1/((Seguimiento!$R$1:$AM$1<>"")*(Seguimiento!$R5:$AM5<>"")),Seguimiento!$R5:$AM5)*100,LOOKUP(2,1/((Seguimiento!$R$1:$AM$1<>"")*(Seguimiento!$R5:$AM5<>"")),Seguimiento!$R5:$AM5)),IFERROR(IF(VALUE(SUBSTITUTE(SUBSTITUTE(LOOKUP(2,1/((Seguimiento!$R$1:$AM$1<>"")*(Seguimiento!$R5:$AM5<>"")),Seguimiento!$R5:$AM5),"%",""),",","."))<=1,VALUE(SUBSTITUTE(SUBSTITUTE(LOOKUP(2,1/((Seguimiento!$R$1:$AM$1<>"")*(Seguimiento!$R5:$AM5<>"")),Seguimiento!$R5:$AM5),"%",""),",","."))*100,VALUE(SUBSTITUTE(SUBSTITUTE(LOOKUP(2,1/((Seguimiento!$R$1:$AM$1<>"")*(Seguimiento!$R5:$AM5<>"")),Seguimiento!$R5:$AM5),"%",""),",","."))),"")))) | S4: =IF(OR(A4="",Q4="Base"),"",IFERROR(INDEX(Seguimiento!$R5:$AM5,MATCH(Q4,Seguimiento!$R$1:$AM$1,0)+1)&"","")) | T4: =IF(A4="","",TODAY()-Config!$B$2+1) | U4: =IF(OR(A4="",N4=""),"",N4-TODAY()) | V4: =IF(A4="","",IF(AND(R4<>"",R4>=100),"Completada",IF(N4="","Sin fecha límite",IF(TODAY()>N4,"Fecha límite vencida",IF(AND(M4<>"",TODAY()<M4),"Por iniciar","En plazo"))))) | W4: =IF(A4="","",IF(IFERROR(INDEX(Seguimiento!$R5:$AM5,MATCH(Config!$B$4,Seguimiento!$R$1:$AM$1,0)),"")="","No","Sí")) | X4: =IF(A4="","",COUNTIF(Seguimiento!$R$1:$AM$1,"<="&Config!$B$4)-SUMPRODUCT((Seguimiento!$R$1:$AM$1<>"")*(Seguimiento!$R$1:$AM$1<=Config!$B$4)*(Seguimiento!$R5:$AM5<>""))) | Y4: =IF(ISNUMBER(SEARCH("Ruta de Vigilancia",C4)),COUNTIF(Hitos_RutaElNino!$C$2:$C$200,"Sí")&" / "&COUNTIF(Hitos_RutaElNino!$A$2:$A$200,"<>"),"") | Z4: =IF(A4="","",IF(Seguimiento!Q5="","",IF(ISNUMBER(Seguimiento!Q5),IF(Seguimiento!Q5<=1,Seguimiento!Q5*100,Seguimiento!Q5),IFERROR(IF(VALUE(SUBSTITUTE(SUBSTITUTE(Seguimiento!Q5,"%",""),",","."))<=1,VALUE(SUBSTITUTE(SUBSTITUTE(Seguimiento!Q5,"%",""),",","."))*100,VALUE(SUBSTITUTE(SUBSTITUTE(Seguimiento!Q5,"%",""),",","."))),""))))
A5: =IF(Seguimiento!A6="","",Seguimiento!A6) | B5: =IF(Seguimiento!A6="","",Seguimiento!B6) | C5: =IF(Seguimiento!A6="","",Seguimiento!C6&"") | D5: =IF(Seguimiento!A6="","",Seguimiento!D6&"") | E5: =IF(Seguimiento!A6="","",Seguimiento!E6&"") | F5: =IF(Seguimiento!A6="","",Seguimiento!F6&"") | G5: =IF(Seguimiento!A6="","",Seguimiento!G6&"") | H5: =IF(Seguimiento!A6="","",Seguimiento!H6&"") | I5: =IF(Seguimiento!A6="","",Seguimiento!I6&"") | J5: =IF(Seguimiento!A6="","",Seguimiento!J6&"") | K5: =IF(Seguimiento!A6="","",Seguimiento!M6&"") | L5: =IF(Seguimiento!A6="","",Seguimiento!N6&"") | M5: =IF(Seguimiento!K6="","",Seguimiento!K6) | N5: =IF(Seguimiento!L6="","",Seguimiento!L6) | O5: =IF(Seguimiento!A6="","",Seguimiento!O6&"") | P5: =IF(Seguimiento!A6="","",Seguimiento!P6&"") | Q5: =IF(A5="","",IFERROR(LOOKUP(2,1/((Seguimiento!$R$1:$AM$1<>"")*(Seguimiento!$R6:$AM6<>"")),Seguimiento!$R$1:$AM$1),"Base")) | R5: =IF(A5="","",IF(ISERROR(LOOKUP(2,1/((Seguimiento!$R$1:$AM$1<>"")*(Seguimiento!$R6:$AM6<>"")),Seguimiento!$R6:$AM6)),IF(Seguimiento!Q6="","",IF(ISNUMBER(Seguimiento!Q6),IF(Seguimiento!Q6<=1,Seguimiento!Q6*100,Seguimiento!Q6),IFERROR(IF(VALUE(SUBSTITUTE(SUBSTITUTE(Seguimiento!Q6,"%",""),",","."))<=1,VALUE(SUBSTITUTE(SUBSTITUTE(Seguimiento!Q6,"%",""),",","."))*100,VALUE(SUBSTITUTE(SUBSTITUTE(Seguimiento!Q6,"%",""),",","."))),""))),IF(ISNUMBER(LOOKUP(2,1/((Seguimiento!$R$1:$AM$1<>"")*(Seguimiento!$R6:$AM6<>"")),Seguimiento!$R6:$AM6)),IF(LOOKUP(2,1/((Seguimiento!$R$1:$AM$1<>"")*(Seguimiento!$R6:$AM6<>"")),Seguimiento!$R6:$AM6)<=1,LOOKUP(2,1/((Seguimiento!$R$1:$AM$1<>"")*(Seguimiento!$R6:$AM6<>"")),Seguimiento!$R6:$AM6)*100,LOOKUP(2,1/((Seguimiento!$R$1:$AM$1<>"")*(Seguimiento!$R6:$AM6<>"")),Seguimiento!$R6:$AM6)),IFERROR(IF(VALUE(SUBSTITUTE(SUBSTITUTE(LOOKUP(2,1/((Seguimiento!$R$1:$AM$1<>"")*(Seguimiento!$R6:$AM6<>"")),Seguimiento!$R6:$AM6),"%",""),",","."))<=1,VALUE(SUBSTITUTE(SUBSTITUTE(LOOKUP(2,1/((Seguimiento!$R$1:$AM$1<>"")*(Seguimiento!$R6:$AM6<>"")),Seguimiento!$R6:$AM6),"%",""),",","."))*100,VALUE(SUBSTITUTE(SUBSTITUTE(LOOKUP(2,1/((Seguimiento!$R$1:$AM$1<>"")*(Seguimiento!$R6:$AM6<>"")),Seguimiento!$R6:$AM6),"%",""),",","."))),"")))) | S5: =IF(OR(A5="",Q5="Base"),"",IFERROR(INDEX(Seguimiento!$R6:$AM6,MATCH(Q5,Seguimiento!$R$1:$AM$1,0)+1)&"","")) | T5: =IF(A5="","",TODAY()-Config!$B$2+1) | U5: =IF(OR(A5="",N5=""),"",N5-TODAY()) | V5: =IF(A5="","",IF(AND(R5<>"",R5>=100),"Completada",IF(N5="","Sin fecha límite",IF(TODAY()>N5,"Fecha límite vencida",IF(AND(M5<>"",TODAY()<M5),"Por iniciar","En plazo"))))) | W5: =IF(A5="","",IF(IFERROR(INDEX(Seguimiento!$R6:$AM6,MATCH(Config!$B$4,Seguimiento!$R$1:$AM$1,0)),"")="","No","Sí")) | X5: =IF(A5="","",COUNTIF(Seguimiento!$R$1:$AM$1,"<="&Config!$B$4)-SUMPRODUCT((Seguimiento!$R$1:$AM$1<>"")*(Seguimiento!$R$1:$AM$1<=Config!$B$4)*(Seguimiento!$R6:$AM6<>""))) | Y5: =IF(ISNUMBER(SEARCH("Ruta de Vigilancia",C5)),COUNTIF(Hitos_RutaElNino!$C$2:$C$200,"Sí")&" / "&COUNTIF(Hitos_RutaElNino!$A$2:$A$200,"<>"),"") | Z5: =IF(A5="","",IF(Seguimiento!Q6="","",IF(ISNUMBER(Seguimiento!Q6),IF(Seguimiento!Q6<=1,Seguimiento!Q6*100,Seguimiento!Q6),IFERROR(IF(VALUE(SUBSTITUTE(SUBSTITUTE(Seguimiento!Q6,"%",""),",","."))<=1,VALUE(SUBSTITUTE(SUBSTITUTE(Seguimiento!Q6,"%",""),",","."))*100,VALUE(SUBSTITUTE(SUBSTITUTE(Seguimiento!Q6,"%",""),",","."))),""))))
A6: =IF(Seguimiento!A7="","",Seguimiento!A7) | B6: =IF(Seguimiento!A7="","",Seguimiento!B7) | C6: =IF(Seguimiento!A7="","",Seguimiento!C7&"") | D6: =IF(Seguimiento!A7="","",Seguimiento!D7&"") | E6: =IF(Seguimiento!A7="","",Seguimiento!E7&"") | F6: =IF(Seguimiento!A7="","",Seguimiento!F7&"") | G6: =IF(Seguimiento!A7="","",Seguimiento!G7&"") | H6: =IF(Seguimiento!A7="","",Seguimiento!H7&"") | I6: =IF(Seguimiento!A7="","",Seguimiento!I7&"") | J6: =IF(Seguimiento!A7="","",Seguimiento!J7&"") | K6: =IF(Seguimiento!A7="","",Seguimiento!M7&"") | L6: =IF(Seguimiento!A7="","",Seguimiento!N7&"") | M6: =IF(Seguimiento!K7="","",Seguimiento!K7) | N6: =IF(Seguimiento!L7="","",Seguimiento!L7) | O6: =IF(Seguimiento!A7="","",Seguimiento!O7&"") | P6: =IF(Seguimiento!A7="","",Seguimiento!P7&"") | Q6: =IF(A6="","",IFERROR(LOOKUP(2,1/((Seguimiento!$R$1:$AM$1<>"")*(Seguimiento!$R7:$AM7<>"")),Seguimiento!$R$1:$AM$1),"Base")) | R6: =IF(A6="","",IF(ISERROR(LOOKUP(2,1/((Seguimiento!$R$1:$AM$1<>"")*(Seguimiento!$R7:$AM7<>"")),Seguimiento!$R7:$AM7)),IF(Seguimiento!Q7="","",IF(ISNUMBER(Seguimiento!Q7),IF(Seguimiento!Q7<=1,Seguimiento!Q7*100,Seguimiento!Q7),IFERROR(IF(VALUE(SUBSTITUTE(SUBSTITUTE(Seguimiento!Q7,"%",""),",","."))<=1,VALUE(SUBSTITUTE(SUBSTITUTE(Seguimiento!Q7,"%",""),",","."))*100,VALUE(SUBSTITUTE(SUBSTITUTE(Seguimiento!Q7,"%",""),",","."))),""))),IF(ISNUMBER(LOOKUP(2,1/((Seguimiento!$R$1:$AM$1<>"")*(Seguimiento!$R7:$AM7<>"")),Seguimiento!$R7:$AM7)),IF(LOOKUP(2,1/((Seguimiento!$R$1:$AM$1<>"")*(Seguimiento!$R7:$AM7<>"")),Seguimiento!$R7:$AM7)<=1,LOOKUP(2,1/((Seguimiento!$R$1:$AM$1<>"")*(Seguimiento!$R7:$AM7<>"")),Seguimiento!$R7:$AM7)*100,LOOKUP(2,1/((Seguimiento!$R$1:$AM$1<>"")*(Seguimiento!$R7:$AM7<>"")),Seguimiento!$R7:$AM7)),IFERROR(IF(VALUE(SUBSTITUTE(SUBSTITUTE(LOOKUP(2,1/((Seguimiento!$R$1:$AM$1<>"")*(Seguimiento!$R7:$AM7<>"")),Seguimiento!$R7:$AM7),"%",""),",","."))<=1,VALUE(SUBSTITUTE(SUBSTITUTE(LOOKUP(2,1/((Seguimiento!$R$1:$AM$1<>"")*(Seguimiento!$R7:$AM7<>"")),Seguimiento!$R7:$AM7),"%",""),",","."))*100,VALUE(SUBSTITUTE(SUBSTITUTE(LOOKUP(2,1/((Seguimiento!$R$1:$AM$1<>"")*(Seguimiento!$R7:$AM7<>"")),Seguimiento!$R7:$AM7),"%",""),",","."))),"")))) | S6: =IF(OR(A6="",Q6="Base"),"",IFERROR(INDEX(Seguimiento!$R7:$AM7,MATCH(Q6,Seguimiento!$R$1:$AM$1,0)+1)&"","")) | T6: =IF(A6="","",TODAY()-Config!$B$2+1) | U6: =IF(OR(A6="",N6=""),"",N6-TODAY()) | V6: =IF(A6="","",IF(AND(R6<>"",R6>=100),"Completada",IF(N6="","Sin fecha límite",IF(TODAY()>N6,"Fecha límite vencida",IF(AND(M6<>"",TODAY()<M6),"Por iniciar","En plazo"))))) | W6: =IF(A6="","",IF(IFERROR(INDEX(Seguimiento!$R7:$AM7,MATCH(Config!$B$4,Seguimiento!$R$1:$AM$1,0)),"")="","No","Sí")) | X6: =IF(A6="","",COUNTIF(Seguimiento!$R$1:$AM$1,"<="&Config!$B$4)-SUMPRODUCT((Seguimiento!$R$1:$AM$1<>"")*(Seguimiento!$R$1:$AM$1<=Config!$B$4)*(Seguimiento!$R7:$AM7<>""))) | Y6: =IF(ISNUMBER(SEARCH("Ruta de Vigilancia",C6)),COUNTIF(Hitos_RutaElNino!$C$2:$C$200,"Sí")&" / "&COUNTIF(Hitos_RutaElNino!$A$2:$A$200,"<>"),"") | Z6: =IF(A6="","",IF(Seguimiento!Q7="","",IF(ISNUMBER(Seguimiento!Q7),IF(Seguimiento!Q7<=1,Seguimiento!Q7*100,Seguimiento!Q7),IFERROR(IF(VALUE(SUBSTITUTE(SUBSTITUTE(Seguimiento!Q7,"%",""),",","."))<=1,VALUE(SUBSTITUTE(SUBSTITUTE(Seguimiento!Q7,"%",""),",","."))*100,VALUE(SUBSTITUTE(SUBSTITUTE(Seguimiento!Q7,"%",""),",","."))),""))))
A7: =IF(Seguimiento!A8="","",Seguimiento!A8) | B7: =IF(Seguimiento!A8="","",Seguimiento!B8) | C7: =IF(Seguimiento!A8="","",Seguimiento!C8&"") | D7: =IF(Seguimiento!A8="","",Seguimiento!D8&"") | E7: =IF(Seguimiento!A8="","",Seguimiento!E8&"") | F7: =IF(Seguimiento!A8="","",Seguimiento!F8&"") | G7: =IF(Seguimiento!A8="","",Seguimiento!G8&"") | H7: =IF(Seguimiento!A8="","",Seguimiento!H8&"") | I7: =IF(Seguimiento!A8="","",Seguimiento!I8&"") | J7: =IF(Seguimiento!A8="","",Seguimiento!J8&"") | K7: =IF(Seguimiento!A8="","",Seguimiento!M8&"") | L7: =IF(Seguimiento!A8="","",Seguimiento!N8&"") | M7: =IF(Seguimiento!K8="","",Seguimiento!K8) | N7: =IF(Seguimiento!L8="","",Seguimiento!L8) | O7: =IF(Seguimiento!A8="","",Seguimiento!O8&"") | P7: =IF(Seguimiento!A8="","",Seguimiento!P8&"") | Q7: =IF(A7="","",IFERROR(LOOKUP(2,1/((Seguimiento!$R$1:$AM$1<>"")*(Seguimiento!$R8:$AM8<>"")),Seguimiento!$R$1:$AM$1),"Base")) | R7: =IF(A7="","",IF(ISERROR(LOOKUP(2,1/((Seguimiento!$R$1:$AM$1<>"")*(Seguimiento!$R8:$AM8<>"")),Seguimiento!$R8:$AM8)),IF(Seguimiento!Q8="","",IF(ISNUMBER(Seguimiento!Q8),IF(Seguimiento!Q8<=1,Seguimiento!Q8*100,Seguimiento!Q8),IFERROR(IF(VALUE(SUBSTITUTE(SUBSTITUTE(Seguimiento!Q8,"%",""),",","."))<=1,VALUE(SUBSTITUTE(SUBSTITUTE(Seguimiento!Q8,"%",""),",","."))*100,VALUE(SUBSTITUTE(SUBSTITUTE(Seguimiento!Q8,"%",""),",","."))),""))),IF(ISNUMBER(LOOKUP(2,1/((Seguimiento!$R$1:$AM$1<>"")*(Seguimiento!$R8:$AM8<>"")),Seguimiento!$R8:$AM8)),IF(LOOKUP(2,1/((Seguimiento!$R$1:$AM$1<>"")*(Seguimiento!$R8:$AM8<>"")),Seguimiento!$R8:$AM8)<=1,LOOKUP(2,1/((Seguimiento!$R$1:$AM$1<>"")*(Seguimiento!$R8:$AM8<>"")),Seguimiento!$R8:$AM8)*100,LOOKUP(2,1/((Seguimiento!$R$1:$AM$1<>"")*(Seguimiento!$R8:$AM8<>"")),Seguimiento!$R8:$AM8)),IFERROR(IF(VALUE(SUBSTITUTE(SUBSTITUTE(LOOKUP(2,1/((Seguimiento!$R$1:$AM$1<>"")*(Seguimiento!$R8:$AM8<>"")),Seguimiento!$R8:$AM8),"%",""),",","."))<=1,VALUE(SUBSTITUTE(SUBSTITUTE(LOOKUP(2,1/((Seguimiento!$R$1:$AM$1<>"")*(Seguimiento!$R8:$AM8<>"")),Seguimiento!$R8:$AM8),"%",""),",","."))*100,VALUE(SUBSTITUTE(SUBSTITUTE(LOOKUP(2,1/((Seguimiento!$R$1:$AM$1<>"")*(Seguimiento!$R8:$AM8<>"")),Seguimiento!$R8:$AM8),"%",""),",","."))),"")))) | S7: =IF(OR(A7="",Q7="Base"),"",IFERROR(INDEX(Seguimiento!$R8:$AM8,MATCH(Q7,Seguimiento!$R$1:$AM$1,0)+1)&"","")) | T7: =IF(A7="","",TODAY()-Config!$B$2+1) | U7: =IF(OR(A7="",N7=""),"",N7-TODAY()) | V7: =IF(A7="","",IF(AND(R7<>"",R7>=100),"Completada",IF(N7="","Sin fecha límite",IF(TODAY()>N7,"Fecha límite vencida",IF(AND(M7<>"",TODAY()<M7),"Por iniciar","En plazo"))))) | W7: =IF(A7="","",IF(IFERROR(INDEX(Seguimiento!$R8:$AM8,MATCH(Config!$B$4,Seguimiento!$R$1:$AM$1,0)),"")="","No","Sí")) | X7: =IF(A7="","",COUNTIF(Seguimiento!$R$1:$AM$1,"<="&Config!$B$4)-SUMPRODUCT((Seguimiento!$R$1:$AM$1<>"")*(Seguimiento!$R$1:$AM$1<=Config!$B$4)*(Seguimiento!$R8:$AM8<>""))) | Y7: =IF(ISNUMBER(SEARCH("Ruta de Vigilancia",C7)),COUNTIF(Hitos_RutaElNino!$C$2:$C$200,"Sí")&" / "&COUNTIF(Hitos_RutaElNino!$A$2:$A$200,"<>"),"") | Z7: =IF(A7="","",IF(Seguimiento!Q8="","",IF(ISNUMBER(Seguimiento!Q8),IF(Seguimiento!Q8<=1,Seguimiento!Q8*100,Seguimiento!Q8),IFERROR(IF(VALUE(SUBSTITUTE(SUBSTITUTE(Seguimiento!Q8,"%",""),",","."))<=1,VALUE(SUBSTITUTE(SUBSTITUTE(Seguimiento!Q8,"%",""),",","."))*100,VALUE(SUBSTITUTE(SUBSTITUTE(Seguimiento!Q8,"%",""),",","."))),""))))
A8: =IF(Seguimiento!A9="","",Seguimiento!A9) | B8: =IF(Seguimiento!A9="","",Seguimiento!B9) | C8: =IF(Seguimiento!A9="","",Seguimiento!C9&"") | D8: =IF(Seguimiento!A9="","",Seguimiento!D9&"") | E8: =IF(Seguimiento!A9="","",Seguimiento!E9&"") | F8: =IF(Seguimiento!A9="","",Seguimiento!F9&"") | G8: =IF(Seguimiento!A9="","",Seguimiento!G9&"") | H8: =IF(Seguimiento!A9="","",Seguimiento!H9&"") | I8: =IF(Seguimiento!A9="","",Seguimiento!I9&"") | J8: =IF(Seguimiento!A9="","",Seguimiento!J9&"") | K8: =IF(Seguimiento!A9="","",Seguimiento!M9&"") | L8: =IF(Seguimiento!A9="","",Seguimiento!N9&"") | M8: =IF(Seguimiento!K9="","",Seguimiento!K9) | N8: =IF(Seguimiento!L9="","",Seguimiento!L9) | O8: =IF(Seguimiento!A9="","",Seguimiento!O9&"") | P8: =IF(Seguimiento!A9="","",Seguimiento!P9&"") | Q8: =IF(A8="","",IFERROR(LOOKUP(2,1/((Seguimiento!$R$1:$AM$1<>"")*(Seguimiento!$R9:$AM9<>"")),Seguimiento!$R$1:$AM$1),"Base")) | R8: =IF(A8="","",IF(ISERROR(LOOKUP(2,1/((Seguimiento!$R$1:$AM$1<>"")*(Seguimiento!$R9:$AM9<>"")),Seguimiento!$R9:$AM9)),IF(Seguimiento!Q9="","",IF(ISNUMBER(Seguimiento!Q9),IF(Seguimiento!Q9<=1,Seguimiento!Q9*100,Seguimiento!Q9),IFERROR(IF(VALUE(SUBSTITUTE(SUBSTITUTE(Seguimiento!Q9,"%",""),",","."))<=1,VALUE(SUBSTITUTE(SUBSTITUTE(Seguimiento!Q9,"%",""),",","."))*100,VALUE(SUBSTITUTE(SUBSTITUTE(Seguimiento!Q9,"%",""),",","."))),""))),IF(ISNUMBER(LOOKUP(2,1/((Seguimiento!$R$1:$AM$1<>"")*(Seguimiento!$R9:$AM9<>"")),Seguimiento!$R9:$AM9)),IF(LOOKUP(2,1/((Seguimiento!$R$1:$AM$1<>"")*(Seguimiento!$R9:$AM9<>"")),Seguimiento!$R9:$AM9)<=1,LOOKUP(2,1/((Seguimiento!$R$1:$AM$1<>"")*(Seguimiento!$R9:$AM9<>"")),Seguimiento!$R9:$AM9)*100,LOOKUP(2,1/((Seguimiento!$R$1:$AM$1<>"")*(Seguimiento!$R9:$AM9<>"")),Seguimiento!$R9:$AM9)),IFERROR(IF(VALUE(SUBSTITUTE(SUBSTITUTE(LOOKUP(2,1/((Seguimiento!$R$1:$AM$1<>"")*(Seguimiento!$R9:$AM9<>"")),Seguimiento!$R9:$AM9),"%",""),",","."))<=1,VALUE(SUBSTITUTE(SUBSTITUTE(LOOKUP(2,1/((Seguimiento!$R$1:$AM$1<>"")*(Seguimiento!$R9:$AM9<>"")),Seguimiento!$R9:$AM9),"%",""),",","."))*100,VALUE(SUBSTITUTE(SUBSTITUTE(LOOKUP(2,1/((Seguimiento!$R$1:$AM$1<>"")*(Seguimiento!$R9:$AM9<>"")),Seguimiento!$R9:$AM9),"%",""),",","."))),"")))) | S8: =IF(OR(A8="",Q8="Base"),"",IFERROR(INDEX(Seguimiento!$R9:$AM9,MATCH(Q8,Seguimiento!$R$1:$AM$1,0)+1)&"","")) | T8: =IF(A8="","",TODAY()-Config!$B$2+1) | U8: =IF(OR(A8="",N8=""),"",N8-TODAY()) | V8: =IF(A8="","",IF(AND(R8<>"",R8>=100),"Completada",IF(N8="","Sin fecha límite",IF(TODAY()>N8,"Fecha límite vencida",IF(AND(M8<>"",TODAY()<M8),"Por iniciar","En plazo"))))) | W8: =IF(A8="","",IF(IFERROR(INDEX(Seguimiento!$R9:$AM9,MATCH(Config!$B$4,Seguimiento!$R$1:$AM$1,0)),"")="","No","Sí")) | X8: =IF(A8="","",COUNTIF(Seguimiento!$R$1:$AM$1,"<="&Config!$B$4)-SUMPRODUCT((Seguimiento!$R$1:$AM$1<>"")*(Seguimiento!$R$1:$AM$1<=Config!$B$4)*(Seguimiento!$R9:$AM9<>""))) | Y8: =IF(ISNUMBER(SEARCH("Ruta de Vigilancia",C8)),COUNTIF(Hitos_RutaElNino!$C$2:$C$200,"Sí")&" / "&COUNTIF(Hitos_RutaElNino!$A$2:$A$200,"<>"),"") | Z8: =IF(A8="","",IF(Seguimiento!Q9="","",IF(ISNUMBER(Seguimiento!Q9),IF(Seguimiento!Q9<=1,Seguimiento!Q9*100,Seguimiento!Q9),IFERROR(IF(VALUE(SUBSTITUTE(SUBSTITUTE(Seguimiento!Q9,"%",""),",","."))<=1,VALUE(SUBSTITUTE(SUBSTITUTE(Seguimiento!Q9,"%",""),",","."))*100,VALUE(SUBSTITUTE(SUBSTITUTE(Seguimiento!Q9,"%",""),",","."))),""))))
A9: =IF(Seguimiento!A10="","",Seguimiento!A10) | B9: =IF(Seguimiento!A10="","",Seguimiento!B10) | C9: =IF(Seguimiento!A10="","",Seguimiento!C10&"") | D9: =IF(Seguimiento!A10="","",Seguimiento!D10&"") | E9: =IF(Seguimiento!A10="","",Seguimiento!E10&"") | F9: =IF(Seguimiento!A10="","",Seguimiento!F10&"") | G9: =IF(Seguimiento!A10="","",Seguimiento!G10&"") | H9: =IF(Seguimiento!A10="","",Seguimiento!H10&"") | I9: =IF(Seguimiento!A10="","",Seguimiento!I10&"") | J9: =IF(Seguimiento!A10="","",Seguimiento!J10&"") | K9: =IF(Seguimiento!A10="","",Seguimiento!M10&"") | L9: =IF(Seguimiento!A10="","",Seguimiento!N10&"") | M9: =IF(Seguimiento!K10="","",Seguimiento!K10) | N9: =IF(Seguimiento!L10="","",Seguimiento!L10) | O9: =IF(Seguimiento!A10="","",Seguimiento!O10&"") | P9: =IF(Seguimiento!A10="","",Seguimiento!P10&"") | Q9: =IF(A9="","",IFERROR(LOOKUP(2,1/((Seguimiento!$R$1:$AM$1<>"")*(Seguimiento!$R10:$AM10<>"")),Seguimiento!$R$1:$AM$1),"Base")) | R9: =IF(A9="","",IF(ISERROR(LOOKUP(2,1/((Seguimiento!$R$1:$AM$1<>"")*(Seguimiento!$R10:$AM10<>"")),Seguimiento!$R10:$AM10)),IF(Seguimiento!Q10="","",IF(ISNUMBER(Seguimiento!Q10),IF(Seguimiento!Q10<=1,Seguimiento!Q10*100,Seguimiento!Q10),IFERROR(IF(VALUE(SUBSTITUTE(SUBSTITUTE(Seguimiento!Q10,"%",""),",","."))<=1,VALUE(SUBSTITUTE(SUBSTITUTE(Seguimiento!Q10,"%",""),",","."))*100,VALUE(SUBSTITUTE(SUBSTITUTE(Seguimiento!Q10,"%",""),",","."))),""))),IF(ISNUMBER(LOOKUP(2,1/((Seguimiento!$R$1:$AM$1<>"")*(Seguimiento!$R10:$AM10<>"")),Seguimiento!$R10:$AM10)),IF(LOOKUP(2,1/((Seguimiento!$R$1:$AM$1<>"")*(Seguimiento!$R10:$AM10<>"")),Seguimiento!$R10:$AM10)<=1,LOOKUP(2,1/((Seguimiento!$R$1:$AM$1<>"")*(Seguimiento!$R10:$AM10<>"")),Seguimiento!$R10:$AM10)*100,LOOKUP(2,1/((Seguimiento!$R$1:$AM$1<>"")*(Seguimiento!$R10:$AM10<>"")),Seguimiento!$R10:$AM10)),IFERROR(IF(VALUE(SUBSTITUTE(SUBSTITUTE(LOOKUP(2,1/((Seguimiento!$R$1:$AM$1<>"")*(Seguimiento!$R10:$AM10<>"")),Seguimiento!$R10:$AM10),"%",""),",","."))<=1,VALUE(SUBSTITUTE(SUBSTITUTE(LOOKUP(2,1/((Seguimiento!$R$1:$AM$1<>"")*(Seguimiento!$R10:$AM10<>"")),Seguimiento!$R10:$AM10),"%",""),",","."))*100,VALUE(SUBSTITUTE(SUBSTITUTE(LOOKUP(2,1/((Seguimiento!$R$1:$AM$1<>"")*(Seguimiento!$R10:$AM10<>"")),Seguimiento!$R10:$AM10),"%",""),",","."))),"")))) | S9: =IF(OR(A9="",Q9="Base"),"",IFERROR(INDEX(Seguimiento!$R10:$AM10,MATCH(Q9,Seguimiento!$R$1:$AM$1,0)+1)&"","")) | T9: =IF(A9="","",TODAY()-Config!$B$2+1) | U9: =IF(OR(A9="",N9=""),"",N9-TODAY()) | V9: =IF(A9="","",IF(AND(R9<>"",R9>=100),"Completada",IF(N9="","Sin fecha límite",IF(TODAY()>N9,"Fecha límite vencida",IF(AND(M9<>"",TODAY()<M9),"Por iniciar","En plazo"))))) | W9: =IF(A9="","",IF(IFERROR(INDEX(Seguimiento!$R10:$AM10,MATCH(Config!$B$4,Seguimiento!$R$1:$AM$1,0)),"")="","No","Sí")) | X9: =IF(A9="","",COUNTIF(Seguimiento!$R$1:$AM$1,"<="&Config!$B$4)-SUMPRODUCT((Seguimiento!$R$1:$AM$1<>"")*(Seguimiento!$R$1:$AM$1<=Config!$B$4)*(Seguimiento!$R10:$AM10<>""))) | Y9: =IF(ISNUMBER(SEARCH("Ruta de Vigilancia",C9)),COUNTIF(Hitos_RutaElNino!$C$2:$C$200,"Sí")&" / "&COUNTIF(Hitos_RutaElNino!$A$2:$A$200,"<>"),"") | Z9: =IF(A9="","",IF(Seguimiento!Q10="","",IF(ISNUMBER(Seguimiento!Q10),IF(Seguimiento!Q10<=1,Seguimiento!Q10*100,Seguimiento!Q10),IFERROR(IF(VALUE(SUBSTITUTE(SUBSTITUTE(Seguimiento!Q10,"%",""),",","."))<=1,VALUE(SUBSTITUTE(SUBSTITUTE(Seguimiento!Q10,"%",""),",","."))*100,VALUE(SUBSTITUTE(SUBSTITUTE(Seguimiento!Q10,"%",""),",","."))),""))))
A10: =IF(Seguimiento!A11="","",Seguimiento!A11) | B10: =IF(Seguimiento!A11="","",Seguimiento!B11) | C10: =IF(Seguimiento!A11="","",Seguimiento!C11&"") | D10: =IF(Seguimiento!A11="","",Seguimiento!D11&"") | E10: =IF(Seguimiento!A11="","",Seguimiento!E11&"") | F10: =IF(Seguimiento!A11="","",Seguimiento!F11&"") | G10: =IF(Seguimiento!A11="","",Seguimiento!G11&"") | H10: =IF(Seguimiento!A11="","",Seguimiento!H11&"") | I10: =IF(Seguimiento!A11="","",Seguimiento!I11&"") | J10: =IF(Seguimiento!A11="","",Seguimiento!J11&"") | K10: =IF(Seguimiento!A11="","",Seguimiento!M11&"") | L10: =IF(Seguimiento!A11="","",Seguimiento!N11&"") | M10: =IF(Seguimiento!K11="","",Seguimiento!K11) | N10: =IF(Seguimiento!L11="","",Seguimiento!L11) | O10: =IF(Seguimiento!A11="","",Seguimiento!O11&"") | P10: =IF(Seguimiento!A11="","",Seguimiento!P11&"") | Q10: =IF(A10="","",IFERROR(LOOKUP(2,1/((Seguimiento!$R$1:$AM$1<>"")*(Seguimiento!$R11:$AM11<>"")),Seguimiento!$R$1:$AM$1),"Base")) | R10: =IF(A10="","",IF(ISERROR(LOOKUP(2,1/((Seguimiento!$R$1:$AM$1<>"")*(Seguimiento!$R11:$AM11<>"")),Seguimiento!$R11:$AM11)),IF(Seguimiento!Q11="","",IF(ISNUMBER(Seguimiento!Q11),IF(Seguimiento!Q11<=1,Seguimiento!Q11*100,Seguimiento!Q11),IFERROR(IF(VALUE(SUBSTITUTE(SUBSTITUTE(Seguimiento!Q11,"%",""),",","."))<=1,VALUE(SUBSTITUTE(SUBSTITUTE(Seguimiento!Q11,"%",""),",","."))*100,VALUE(SUBSTITUTE(SUBSTITUTE(Seguimiento!Q11,"%",""),",","."))),""))),IF(ISNUMBER(LOOKUP(2,1/((Seguimiento!$R$1:$AM$1<>"")*(Seguimiento!$R11:$AM11<>"")),Seguimiento!$R11:$AM11)),IF(LOOKUP(2,1/((Seguimiento!$R$1:$AM$1<>"")*(Seguimiento!$R11:$AM11<>"")),Seguimiento!$R11:$AM11)<=1,LOOKUP(2,1/((Seguimiento!$R$1:$AM$1<>"")*(Seguimiento!$R11:$AM11<>"")),Seguimiento!$R11:$AM11)*100,LOOKUP(2,1/((Seguimiento!$R$1:$AM$1<>"")*(Seguimiento!$R11:$AM11<>"")),Seguimiento!$R11:$AM11)),IFERROR(IF(VALUE(SUBSTITUTE(SUBSTITUTE(LOOKUP(2,1/((Seguimiento!$R$1:$AM$1<>"")*(Seguimiento!$R11:$AM11<>"")),Seguimiento!$R11:$AM11),"%",""),",","."))<=1,VALUE(SUBSTITUTE(SUBSTITUTE(LOOKUP(2,1/((Seguimiento!$R$1:$AM$1<>"")*(Seguimiento!$R11:$AM11<>"")),Seguimiento!$R11:$AM11),"%",""),",","."))*100,VALUE(SUBSTITUTE(SUBSTITUTE(LOOKUP(2,1/((Seguimiento!$R$1:$AM$1<>"")*(Seguimiento!$R11:$AM11<>"")),Seguimiento!$R11:$AM11),"%",""),",","."))),"")))) | S10: =IF(OR(A10="",Q10="Base"),"",IFERROR(INDEX(Seguimiento!$R11:$AM11,MATCH(Q10,Seguimiento!$R$1:$AM$1,0)+1)&"","")) | T10: =IF(A10="","",TODAY()-Config!$B$2+1) | U10: =IF(OR(A10="",N10=""),"",N10-TODAY()) | V10: =IF(A10="","",IF(AND(R10<>"",R10>=100),"Completada",IF(N10="","Sin fecha límite",IF(TODAY()>N10,"Fecha límite vencida",IF(AND(M10<>"",TODAY()<M10),"Por iniciar","En plazo"))))) | W10: =IF(A10="","",IF(IFERROR(INDEX(Seguimiento!$R11:$AM11,MATCH(Config!$B$4,Seguimiento!$R$1:$AM$1,0)),"")="","No","Sí")) | X10: =IF(A10="","",COUNTIF(Seguimiento!$R$1:$AM$1,"<="&Config!$B$4)-SUMPRODUCT((Seguimiento!$R$1:$AM$1<>"")*(Seguimiento!$R$1:$AM$1<=Config!$B$4)*(Seguimiento!$R11:$AM11<>""))) | Y10: =IF(ISNUMBER(SEARCH("Ruta de Vigilancia",C10)),COUNTIF(Hitos_RutaElNino!$C$2:$C$200,"Sí")&" / "&COUNTIF(Hitos_RutaElNino!$A$2:$A$200,"<>"),"") | Z10: =IF(A10="","",IF(Seguimiento!Q11="","",IF(ISNUMBER(Seguimiento!Q11),IF(Seguimiento!Q11<=1,Seguimiento!Q11*100,Seguimiento!Q11),IFERROR(IF(VALUE(SUBSTITUTE(SUBSTITUTE(Seguimiento!Q11,"%",""),",","."))<=1,VALUE(SUBSTITUTE(SUBSTITUTE(Seguimiento!Q11,"%",""),",","."))*100,VALUE(SUBSTITUTE(SUBSTITUTE(Seguimiento!Q11,"%",""),",","."))),""))))
A11: =IF(Seguimiento!A12="","",Seguimiento!A12) | B11: =IF(Seguimiento!A12="","",Seguimiento!B12) | C11: =IF(Seguimiento!A12="","",Seguimiento!C12&"") | D11: =IF(Seguimiento!A12="","",Seguimiento!D12&"") | E11: =IF(Seguimiento!A12="","",Seguimiento!E12&"") | F11: =IF(Seguimiento!A12="","",Seguimiento!F12&"") | G11: =IF(Seguimiento!A12="","",Seguimiento!G12&"") | H11: =IF(Seguimiento!A12="","",Seguimiento!H12&"") | I11: =IF(Seguimiento!A12="","",Seguimiento!I12&"") | J11: =IF(Seguimiento!A12="","",Seguimiento!J12&"") | K11: =IF(Seguimiento!A12="","",Seguimiento!M12&"") | L11: =IF(Seguimiento!A12="","",Seguimiento!N12&"") | M11: =IF(Seguimiento!K12="","",Seguimiento!K12) | N11: =IF(Seguimiento!L12="","",Seguimiento!L12) | O11: =IF(Seguimiento!A12="","",Seguimiento!O12&"") | P11: =IF(Seguimiento!A12="","",Seguimiento!P12&"") | Q11: =IF(A11="","",IFERROR(LOOKUP(2,1/((Seguimiento!$R$1:$AM$1<>"")*(Seguimiento!$R12:$AM12<>"")),Seguimiento!$R$1:$AM$1),"Base")) | R11: =IF(A11="","",IF(ISERROR(LOOKUP(2,1/((Seguimiento!$R$1:$AM$1<>"")*(Seguimiento!$R12:$AM12<>"")),Seguimiento!$R12:$AM12)),IF(Seguimiento!Q12="","",IF(ISNUMBER(Seguimiento!Q12),IF(Seguimiento!Q12<=1,Seguimiento!Q12*100,Seguimiento!Q12),IFERROR(IF(VALUE(SUBSTITUTE(SUBSTITUTE(Seguimiento!Q12,"%",""),",","."))<=1,VALUE(SUBSTITUTE(SUBSTITUTE(Seguimiento!Q12,"%",""),",","."))*100,VALUE(SUBSTITUTE(SUBSTITUTE(Seguimiento!Q12,"%",""),",","."))),""))),IF(ISNUMBER(LOOKUP(2,1/((Seguimiento!$R$1:$AM$1<>"")*(Seguimiento!$R12:$AM12<>"")),Seguimiento!$R12:$AM12)),IF(LOOKUP(2,1/((Seguimiento!$R$1:$AM$1<>"")*(Seguimiento!$R12:$AM12<>"")),Seguimiento!$R12:$AM12)<=1,LOOKUP(2,1/((Seguimiento!$R$1:$AM$1<>"")*(Seguimiento!$R12:$AM12<>"")),Seguimiento!$R12:$AM12)*100,LOOKUP(2,1/((Seguimiento!$R$1:$AM$1<>"")*(Seguimiento!$R12:$AM12<>"")),Seguimiento!$R12:$AM12)),IFERROR(IF(VALUE(SUBSTITUTE(SUBSTITUTE(LOOKUP(2,1/((Seguimiento!$R$1:$AM$1<>"")*(Seguimiento!$R12:$AM12<>"")),Seguimiento!$R12:$AM12),"%",""),",","."))<=1,VALUE(SUBSTITUTE(SUBSTITUTE(LOOKUP(2,1/((Seguimiento!$R$1:$AM$1<>"")*(Seguimiento!$R12:$AM12<>"")),Seguimiento!$R12:$AM12),"%",""),",","."))*100,VALUE(SUBSTITUTE(SUBSTITUTE(LOOKUP(2,1/((Seguimiento!$R$1:$AM$1<>"")*(Seguimiento!$R12:$AM12<>"")),Seguimiento!$R12:$AM12),"%",""),",","."))),"")))) | S11: =IF(OR(A11="",Q11="Base"),"",IFERROR(INDEX(Seguimiento!$R12:$AM12,MATCH(Q11,Seguimiento!$R$1:$AM$1,0)+1)&"","")) | T11: =IF(A11="","",TODAY()-Config!$B$2+1) | U11: =IF(OR(A11="",N11=""),"",N11-TODAY()) | V11: =IF(A11="","",IF(AND(R11<>"",R11>=100),"Completada",IF(N11="","Sin fecha límite",IF(TODAY()>N11,"Fecha límite vencida",IF(AND(M11<>"",TODAY()<M11),"Por iniciar","En plazo"))))) | W11: =IF(A11="","",IF(IFERROR(INDEX(Seguimiento!$R12:$AM12,MATCH(Config!$B$4,Seguimiento!$R$1:$AM$1,0)),"")="","No","Sí")) | X11: =IF(A11="","",COUNTIF(Seguimiento!$R$1:$AM$1,"<="&Config!$B$4)-SUMPRODUCT((Seguimiento!$R$1:$AM$1<>"")*(Seguimiento!$R$1:$AM$1<=Config!$B$4)*(Seguimiento!$R12:$AM12<>""))) | Y11: =IF(ISNUMBER(SEARCH("Ruta de Vigilancia",C11)),COUNTIF(Hitos_RutaElNino!$C$2:$C$200,"Sí")&" / "&COUNTIF(Hitos_RutaElNino!$A$2:$A$200,"<>"),"") | Z11: =IF(A11="","",IF(Seguimiento!Q12="","",IF(ISNUMBER(Seguimiento!Q12),IF(Seguimiento!Q12<=1,Seguimiento!Q12*100,Seguimiento!Q12),IFERROR(IF(VALUE(SUBSTITUTE(SUBSTITUTE(Seguimiento!Q12,"%",""),",","."))<=1,VALUE(SUBSTITUTE(SUBSTITUTE(Seguimiento!Q12,"%",""),",","."))*100,VALUE(SUBSTITUTE(SUBSTITUTE(Seguimiento!Q12,"%",""),",","."))),""))))
A12: =IF(Seguimiento!A13="","",Seguimiento!A13) | B12: =IF(Seguimiento!A13="","",Seguimiento!B13) | C12: =IF(Seguimiento!A13="","",Seguimiento!C13&"") | D12: =IF(Seguimiento!A13="","",Seguimiento!D13&"") | E12: =IF(Seguimiento!A13="","",Seguimiento!E13&"") | F12: =IF(Seguimiento!A13="","",Seguimiento!F13&"") | G12: =IF(Seguimiento!A13="","",Seguimiento!G13&"") | H12: =IF(Seguimiento!A13="","",Seguimiento!H13&"") | I12: =IF(Seguimiento!A13="","",Seguimiento!I13&"") | J12: =IF(Seguimiento!A13="","",Seguimiento!J13&"") | K12: =IF(Seguimiento!A13="","",Seguimiento!M13&"") | L12: =IF(Seguimiento!A13="","",Seguimiento!N13&"") | M12: =IF(Seguimiento!K13="","",Seguimiento!K13) | N12: =IF(Seguimiento!L13="","",Seguimiento!L13) | O12: =IF(Seguimiento!A13="","",Seguimiento!O13&"") | P12: =IF(Seguimiento!A13="","",Seguimiento!P13&"") | Q12: =IF(A12="","",IFERROR(LOOKUP(2,1/((Seguimiento!$R$1:$AM$1<>"")*(Seguimiento!$R13:$AM13<>"")),Seguimiento!$R$1:$AM$1),"Base")) | R12: =IF(A12="","",IF(ISERROR(LOOKUP(2,1/((Seguimiento!$R$1:$AM$1<>"")*(Seguimiento!$R13:$AM13<>"")),Seguimiento!$R13:$AM13)),IF(Seguimiento!Q13="","",IF(ISNUMBER(Seguimiento!Q13),IF(Seguimiento!Q13<=1,Seguimiento!Q13*100,Seguimiento!Q13),IFERROR(IF(VALUE(SUBSTITUTE(SUBSTITUTE(Seguimiento!Q13,"%",""),",","."))<=1,VALUE(SUBSTITUTE(SUBSTITUTE(Seguimiento!Q13,"%",""),",","."))*100,VALUE(SUBSTITUTE(SUBSTITUTE(Seguimiento!Q13,"%",""),",","."))),""))),IF(ISNUMBER(LOOKUP(2,1/((Seguimiento!$R$1:$AM$1<>"")*(Seguimiento!$R13:$AM13<>"")),Seguimiento!$R13:$AM13)),IF(LOOKUP(2,1/((Seguimiento!$R$1:$AM$1<>"")*(Seguimiento!$R13:$AM13<>"")),Seguimiento!$R13:$AM13)<=1,LOOKUP(2,1/((Seguimiento!$R$1:$AM$1<>"")*(Seguimiento!$R13:$AM13<>"")),Seguimiento!$R13:$AM13)*100,LOOKUP(2,1/((Seguimiento!$R$1:$AM$1<>"")*(Seguimiento!$R13:$AM13<>"")),Seguimiento!$R13:$AM13)),IFERROR(IF(VALUE(SUBSTITUTE(SUBSTITUTE(LOOKUP(2,1/((Seguimiento!$R$1:$AM$1<>"")*(Seguimiento!$R13:$AM13<>"")),Seguimiento!$R13:$AM13),"%",""),",","."))<=1,VALUE(SUBSTITUTE(SUBSTITUTE(LOOKUP(2,1/((Seguimiento!$R$1:$AM$1<>"")*(Seguimiento!$R13:$AM13<>"")),Seguimiento!$R13:$AM13),"%",""),",","."))*100,VALUE(SUBSTITUTE(SUBSTITUTE(LOOKUP(2,1/((Seguimiento!$R$1:$AM$1<>"")*(Seguimiento!$R13:$AM13<>"")),Seguimiento!$R13:$AM13),"%",""),",","."))),"")))) | S12: =IF(OR(A12="",Q12="Base"),"",IFERROR(INDEX(Seguimiento!$R13:$AM13,MATCH(Q12,Seguimiento!$R$1:$AM$1,0)+1)&"","")) | T12: =IF(A12="","",TODAY()-Config!$B$2+1) | U12: =IF(OR(A12="",N12=""),"",N12-TODAY()) | V12: =IF(A12="","",IF(AND(R12<>"",R12>=100),"Completada",IF(N12="","Sin fecha límite",IF(TODAY()>N12,"Fecha límite vencida",IF(AND(M12<>"",TODAY()<M12),"Por iniciar","En plazo"))))) | W12: =IF(A12="","",IF(IFERROR(INDEX(Seguimiento!$R13:$AM13,MATCH(Config!$B$4,Seguimiento!$R$1:$AM$1,0)),"")="","No","Sí")) | X12: =IF(A12="","",COUNTIF(Seguimiento!$R$1:$AM$1,"<="&Config!$B$4)-SUMPRODUCT((Seguimiento!$R$1:$AM$1<>"")*(Seguimiento!$R$1:$AM$1<=Config!$B$4)*(Seguimiento!$R13:$AM13<>""))) | Y12: =IF(ISNUMBER(SEARCH("Ruta de Vigilancia",C12)),COUNTIF(Hitos_RutaElNino!$C$2:$C$200,"Sí")&" / "&COUNTIF(Hitos_RutaElNino!$A$2:$A$200,"<>"),"") | Z12: =IF(A12="","",IF(Seguimiento!Q13="","",IF(ISNUMBER(Seguimiento!Q13),IF(Seguimiento!Q13<=1,Seguimiento!Q13*100,Seguimiento!Q13),IFERROR(IF(VALUE(SUBSTITUTE(SUBSTITUTE(Seguimiento!Q13,"%",""),",","."))<=1,VALUE(SUBSTITUTE(SUBSTITUTE(Seguimiento!Q13,"%",""),",","."))*100,VALUE(SUBSTITUTE(SUBSTITUTE(Seguimiento!Q13,"%",""),",","."))),""))))
A13: =IF(Seguimiento!A14="","",Seguimiento!A14) | B13: =IF(Seguimiento!A14="","",Seguimiento!B14) | C13: =IF(Seguimiento!A14="","",Seguimiento!C14&"") | D13: =IF(Seguimiento!A14="","",Seguimiento!D14&"") | E13: =IF(Seguimiento!A14="","",Seguimiento!E14&"") | F13: =IF(Seguimiento!A14="","",Seguimiento!F14&"") | G13: =IF(Seguimiento!A14="","",Seguimiento!G14&"") | H13: =IF(Seguimiento!A14="","",Seguimiento!H14&"") | I13: =IF(Seguimiento!A14="","",Seguimiento!I14&"") | J13: =IF(Seguimiento!A14="","",Seguimiento!J14&"") | K13: =IF(Seguimiento!A14="","",Seguimiento!M14&"") | L13: =IF(Seguimiento!A14="","",Seguimiento!N14&"") | M13: =IF(Seguimiento!K14="","",Seguimiento!K14) | N13: =IF(Seguimiento!L14="","",Seguimiento!L14) | O13: =IF(Seguimiento!A14="","",Seguimiento!O14&"") | P13: =IF(Seguimiento!A14="","",Seguimiento!P14&"") | Q13: =IF(A13="","",IFERROR(LOOKUP(2,1/((Seguimiento!$R$1:$AM$1<>"")*(Seguimiento!$R14:$AM14<>"")),Seguimiento!$R$1:$AM$1),"Base")) | R13: =IF(A13="","",IF(ISERROR(LOOKUP(2,1/((Seguimiento!$R$1:$AM$1<>"")*(Seguimiento!$R14:$AM14<>"")),Seguimiento!$R14:$AM14)),IF(Seguimiento!Q14="","",IF(ISNUMBER(Seguimiento!Q14),IF(Seguimiento!Q14<=1,Seguimiento!Q14*100,Seguimiento!Q14),IFERROR(IF(VALUE(SUBSTITUTE(SUBSTITUTE(Seguimiento!Q14,"%",""),",","."))<=1,VALUE(SUBSTITUTE(SUBSTITUTE(Seguimiento!Q14,"%",""),",","."))*100,VALUE(SUBSTITUTE(SUBSTITUTE(Seguimiento!Q14,"%",""),",","."))),""))),IF(ISNUMBER(LOOKUP(2,1/((Seguimiento!$R$1:$AM$1<>"")*(Seguimiento!$R14:$AM14<>"")),Seguimiento!$R14:$AM14)),IF(LOOKUP(2,1/((Seguimiento!$R$1:$AM$1<>"")*(Seguimiento!$R14:$AM14<>"")),Seguimiento!$R14:$AM14)<=1,LOOKUP(2,1/((Seguimiento!$R$1:$AM$1<>"")*(Seguimiento!$R14:$AM14<>"")),Seguimiento!$R14:$AM14)*100,LOOKUP(2,1/((Seguimiento!$R$1:$AM$1<>"")*(Seguimiento!$R14:$AM14<>"")),Seguimiento!$R14:$AM14)),IFERROR(IF(VALUE(SUBSTITUTE(SUBSTITUTE(LOOKUP(2,1/((Seguimiento!$R$1:$AM$1<>"")*(Seguimiento!$R14:$AM14<>"")),Seguimiento!$R14:$AM14),"%",""),",","."))<=1,VALUE(SUBSTITUTE(SUBSTITUTE(LOOKUP(2,1/((Seguimiento!$R$1:$AM$1<>"")*(Seguimiento!$R14:$AM14<>"")),Seguimiento!$R14:$AM14),"%",""),",","."))*100,VALUE(SUBSTITUTE(SUBSTITUTE(LOOKUP(2,1/((Seguimiento!$R$1:$AM$1<>"")*(Seguimiento!$R14:$AM14<>"")),Seguimiento!$R14:$AM14),"%",""),",","."))),"")))) | S13: =IF(OR(A13="",Q13="Base"),"",IFERROR(INDEX(Seguimiento!$R14:$AM14,MATCH(Q13,Seguimiento!$R$1:$AM$1,0)+1)&"","")) | T13: =IF(A13="","",TODAY()-Config!$B$2+1) | U13: =IF(OR(A13="",N13=""),"",N13-TODAY()) | V13: =IF(A13="","",IF(AND(R13<>"",R13>=100),"Completada",IF(N13="","Sin fecha límite",IF(TODAY()>N13,"Fecha límite vencida",IF(AND(M13<>"",TODAY()<M13),"Por iniciar","En plazo"))))) | W13: =IF(A13="","",IF(IFERROR(INDEX(Seguimiento!$R14:$AM14,MATCH(Config!$B$4,Seguimiento!$R$1:$AM$1,0)),"")="","No","Sí")) | X13: =IF(A13="","",COUNTIF(Seguimiento!$R$1:$AM$1,"<="&Config!$B$4)-SUMPRODUCT((Seguimiento!$R$1:$AM$1<>"")*(Seguimiento!$R$1:$AM$1<=Config!$B$4)*(Seguimiento!$R14:$AM14<>""))) | Y13: =IF(ISNUMBER(SEARCH("Ruta de Vigilancia",C13)),COUNTIF(Hitos_RutaElNino!$C$2:$C$200,"Sí")&" / "&COUNTIF(Hitos_RutaElNino!$A$2:$A$200,"<>"),"") | Z13: =IF(A13="","",IF(Seguimiento!Q14="","",IF(ISNUMBER(Seguimiento!Q14),IF(Seguimiento!Q14<=1,Seguimiento!Q14*100,Seguimiento!Q14),IFERROR(IF(VALUE(SUBSTITUTE(SUBSTITUTE(Seguimiento!Q14,"%",""),",","."))<=1,VALUE(SUBSTITUTE(SUBSTITUTE(Seguimiento!Q14,"%",""),",","."))*100,VALUE(SUBSTITUTE(SUBSTITUTE(Seguimiento!Q14,"%",""),",","."))),""))))
... A24: =IF(Seguimiento!A25="","",Seguimiento!A25) | B24: =IF(Seguimiento!A25="","",Seguimiento!B25) | C24: =IF(Seguimiento!A25="","",Seguimiento!C25&"") | D24: =IF(Seguimiento!A25="","",Seguimiento!D25&"") | E24: =IF(Seguimiento!A25="","",Seguimiento!E25&"") | F24: =IF(Seguimiento!A25="","",Seguimiento!F25&"") | G24: =IF(Seguimiento!A25="","",Seguimiento!G25&"") | H24: =IF(Seguimiento!A25="","",Seguimiento!H25&"") | I24: =IF(Seguimiento!A25="","",Seguimiento!I25&"") | J24: =IF(Seguimiento!A25="","",Seguimiento!J25&"") | K24: =IF(Seguimiento!A25="","",Seguimiento!M25&"") | L24: =IF(Seguimiento!A25="","",Seguimiento!N25&"") | M24: =IF(Seguimiento!K25="","",Seguimiento!K25) | N24: =IF(Seguimiento!L25="","",Seguimiento!L25) | O24: =IF(Seguimiento!A25="","",Seguimiento!O25&"") | P24: =IF(Seguimiento!A25="","",Seguimiento!P25&"") | Q24: =IF(A24="","",IFERROR(LOOKUP(2,1/((Seguimiento!$R$1:$AM$1<>"")*(Seguimiento!$R25:$AM25<>"")),Seguimiento!$R$1:$AM$1),"Base")) | R24: =IF(A24="","",IF(ISERROR(LOOKUP(2,1/((Seguimiento!$R$1:$AM$1<>"")*(Seguimiento!$R25:$AM25<>"")),Seguimiento!$R25:$AM25)),IF(Seguimiento!Q25="","",IF(ISNUMBER(Seguimiento!Q25),IF(Seguimiento!Q25<=1,Seguimiento!Q25*100,Seguimiento!Q25),IFERROR(IF(VALUE(SUBSTITUTE(SUBSTITUTE(Seguimiento!Q25,"%",""),",","."))<=1,VALUE(SUBSTITUTE(SUBSTITUTE(Seguimiento!Q25,"%",""),",","."))*100,VALUE(SUBSTITUTE(SUBSTITUTE(Seguimiento!Q25,"%",""),",","."))),""))),IF(ISNUMBER(LOOKUP(2,1/((Seguimiento!$R$1:$AM$1<>"")*(Seguimiento!$R25:$AM25<>"")),Seguimiento!$R25:$AM25)),IF(LOOKUP(2,1/((Seguimiento!$R$1:$AM$1<>"")*(Seguimiento!$R25:$AM25<>"")),Seguimiento!$R25:$AM25)<=1,LOOKUP(2,1/((Seguimiento!$R$1:$AM$1<>"")*(Seguimiento!$R25:$AM25<>"")),Seguimiento!$R25:$AM25)*100,LOOKUP(2,1/((Seguimiento!$R$1:$AM$1<>"")*(Seguimiento!$R25:$AM25<>"")),Seguimiento!$R25:$AM25)),IFERROR(IF(VALUE(SUBSTITUTE(SUBSTITUTE(LOOKUP(2,1/((Seguimiento!$R$1:$AM$1<>"")*(Seguimiento!$R25:$AM25<>"")),Seguimiento!$R25:$AM25),"%",""),",","."))<=1,VALUE(SUBSTITUTE(SUBSTITUTE(LOOKUP(2,1/((Seguimiento!$R$1:$AM$1<>"")*(Seguimiento!$R25:$AM25<>"")),Seguimiento!$R25:$AM25),"%",""),",","."))*100,VALUE(SUBSTITUTE(SUBSTITUTE(LOOKUP(2,1/((Seguimiento!$R$1:$AM$1<>"")*(Seguimiento!$R25:$AM25<>"")),Seguimiento!$R25:$AM25),"%",""),",","."))),"")))) | S24: =IF(OR(A24="",Q24="Base"),"",IFERROR(INDEX(Seguimiento!$R25:$AM25,MATCH(Q24,Seguimiento!$R$1:$AM$1,0)+1)&"","")) | T24: =IF(A24="","",TODAY()-Config!$B$2+1) | U24: =IF(OR(A24="",N24=""),"",N24-TODAY()) | V24: =IF(A24="","",IF(AND(R24<>"",R24>=100),"Completada",IF(N24="","Sin fecha límite",IF(TODAY()>N24,"Fecha límite vencida",IF(AND(M24<>"",TODAY()<M24),"Por iniciar","En plazo"))))) | W24: =IF(A24="","",IF(IFERROR(INDEX(Seguimiento!$R25:$AM25,MATCH(Config!$B$4,Seguimiento!$R$1:$AM$1,0)),"")="","No","Sí")) | X24: =IF(A24="","",COUNTIF(Seguimiento!$R$1:$AM$1,"<="&Config!$B$4)-SUMPRODUCT((Seguimiento!$R$1:$AM$1<>"")*(Seguimiento!$R$1:$AM$1<=Config!$B$4)*(Seguimiento!$R25:$AM25<>""))) | Y24: =IF(ISNUMBER(SEARCH("Ruta de Vigilancia",C24)),COUNTIF(Hitos_RutaElNino!$C$2:$C$200,"Sí")&" / "&COUNTIF(Hitos_RutaElNino!$A$2:$A$200,"<>"),"") | Z24: =IF(A24="","",IF(Seguimiento!Q25="","",IF(ISNUMBER(Seguimiento!Q25),IF(Seguimiento!Q25<=1,Seguimiento!Q25*100,Seguimiento!Q25),IFERROR(IF(VALUE(SUBSTITUTE(SUBSTITUTE(Seguimiento!Q25,"%",""),",","."))<=1,VALUE(SUBSTITUTE(SUBSTITUTE(Seguimiento!Q25,"%",""),",","."))*100,VALUE(SUBSTITUTE(SUBSTITUTE(Seguimiento!Q25,"%",""),",","."))),""))))

Sheet Historial
A1: ID | B1: Dirección | C1: Nombre corto | D1: Fecha de corte | E1: Avance (%) | F1: Acciones
A2: =IF(Seguimiento!$A$3="","",Seguimiento!$A$3) | B2: =IF(Seguimiento!$A$3="","",Seguimiento!$B$3) | C2: =IF(Seguimiento!$A$3="","",Seguimiento!$C$3&"") | D2: 46297 | E2: =IF(Seguimiento!$Q$3="","",IF(ISNUMBER(Seguimiento!$Q$3),IF(Seguimiento!$Q$3<=1,Seguimiento!$Q$3*100,Seguimiento!$Q$3),IFERROR(IF(VALUE(SUBSTITUTE(SUBSTITUTE(Seguimiento!$Q$3,"%",""),",","."))<=1,VALUE(SUBSTITUTE(SUBSTITUTE(Seguimiento!$Q$3,"%",""),",","."))*100,VALUE(SUBSTITUTE(SUBSTITUTE(Seguimiento!$Q$3,"%",""),",","."))),""))) | F2: =IF(Seguimiento!$Q$3="","","Avance inicial (matriz MINAM)")
A3: =IF(Seguimiento!$A$3="","",Seguimiento!$A$3) | B3: =IF(Seguimiento!$A$3="","",Seguimiento!$B$3) | C3: =IF(Seguimiento!$A$3="","",Seguimiento!$C$3&"") | D3: 46304 | E3: =IF(Seguimiento!$R$3="","",IF(ISNUMBER(Seguimiento!$R$3),IF(Seguimiento!$R$3<=1,Seguimiento!$R$3*100,Seguimiento!$R$3),IFERROR(IF(VALUE(SUBSTITUTE(SUBSTITUTE(Seguimiento!$R$3,"%",""),",","."))<=1,VALUE(SUBSTITUTE(SUBSTITUTE(Seguimiento!$R$3,"%",""),",","."))*100,VALUE(SUBSTITUTE(SUBSTITUTE(Seguimiento!$R$3,"%",""),",","."))),""))) | F3: =IF(Seguimiento!$R$3="","",Seguimiento!$S$3&"")
A4: =IF(Seguimiento!$A$3="","",Seguimiento!$A$3) | B4: =IF(Seguimiento!$A$3="","",Seguimiento!$B$3) | C4: =IF(Seguimiento!$A$3="","",Seguimiento!$C$3&"") | D4: 46311 | E4: =IF(Seguimiento!$T$3="","",IF(ISNUMBER(Seguimiento!$T$3),IF(Seguimiento!$T$3<=1,Seguimiento!$T$3*100,Seguimiento!$T$3),IFERROR(IF(VALUE(SUBSTITUTE(SUBSTITUTE(Seguimiento!$T$3,"%",""),",","."))<=1,VALUE(SUBSTITUTE(SUBSTITUTE(Seguimiento!$T$3,"%",""),",","."))*100,VALUE(SUBSTITUTE(SUBSTITUTE(Seguimiento!$T$3,"%",""),",","."))),""))) | F4: =IF(Seguimiento!$T$3="","",Seguimiento!$U$3&"")
A5: =IF(Seguimiento!$A$3="","",Seguimiento!$A$3) | B5: =IF(Seguimiento!$A$3="","",Seguimiento!$B$3) | C5: =IF(Seguimiento!$A$3="","",Seguimiento!$C$3&"") | D5: 46318 | E5: =IF(Seguimiento!$V$3="","",IF(ISNUMBER(Seguimiento!$V$3),IF(Seguimiento!$V$3<=1,Seguimiento!$V$3*100,Seguimiento!$V$3),IFERROR(IF(VALUE(SUBSTITUTE(SUBSTITUTE(Seguimiento!$V$3,"%",""),",","."))<=1,VALUE(SUBSTITUTE(SUBSTITUTE(Seguimiento!$V$3,"%",""),",","."))*100,VALUE(SUBSTITUTE(SUBSTITUTE(Seguimiento!$V$3,"%",""),",","."))),""))) | F5: =IF(Seguimiento!$V$3="","",Seguimiento!$W$3&"")
A6: =IF(Seguimiento!$A$3="","",Seguimiento!$A$3) | B6: =IF(Seguimiento!$A$3="","",Seguimiento!$B$3) | C6: =IF(Seguimiento!$A$3="","",Seguimiento!$C$3&"") | D6: 46325 | E6: =IF(Seguimiento!$X$3="","",IF(ISNUMBER(Seguimiento!$X$3),IF(Seguimiento!$X$3<=1,Seguimiento!$X$3*100,Seguimiento!$X$3),IFERROR(IF(VALUE(SUBSTITUTE(SUBSTITUTE(Seguimiento!$X$3,"%",""),",","."))<=1,VALUE(SUBSTITUTE(SUBSTITUTE(Seguimiento!$X$3,"%",""),",","."))*100,VALUE(SUBSTITUTE(SUBSTITUTE(Seguimiento!$X$3,"%",""),",","."))),""))) | F6: =IF(Seguimiento!$X$3="","",Seguimiento!$Y$3&"")
A7: =IF(Seguimiento!$A$3="","",Seguimiento!$A$3) | B7: =IF(Seguimiento!$A$3="","",Seguimiento!$B$3) | C7: =IF(Seguimiento!$A$3="","",Seguimiento!$C$3&"") | D7: 46332 | E7: =IF(Seguimiento!$Z$3="","",IF(ISNUMBER(Seguimiento!$Z$3),IF(Seguimiento!$Z$3<=1,Seguimiento!$Z$3*100,Seguimiento!$Z$3),IFERROR(IF(VALUE(SUBSTITUTE(SUBSTITUTE(Seguimiento!$Z$3,"%",""),",","."))<=1,VALUE(SUBSTITUTE(SUBSTITUTE(Seguimiento!$Z$3,"%",""),",","."))*100,VALUE(SUBSTITUTE(SUBSTITUTE(Seguimiento!$Z$3,"%",""),",","."))),""))) | F7: =IF(Seguimiento!$Z$3="","",Seguimiento!$AA$3&"")
A8: =IF(Seguimiento!$A$3="","",Seguimiento!$A$3) | B8: =IF(Seguimiento!$A$3="","",Seguimiento!$B$3) | C8: =IF(Seguimiento!$A$3="","",Seguimiento!$C$3&"") | D8: 46339 | E8: =IF(Seguimiento!$AB$3="","",IF(ISNUMBER(Seguimiento!$AB$3),IF(Seguimiento!$AB$3<=1,Seguimiento!$AB$3*100,Seguimiento!$AB$3),IFERROR(IF(VALUE(SUBSTITUTE(SUBSTITUTE(Seguimiento!$AB$3,"%",""),",","."))<=1,VALUE(SUBSTITUTE(SUBSTITUTE(Seguimiento!$AB$3,"%",""),",","."))*100,VALUE(SUBSTITUTE(SUBSTITUTE(Seguimiento!$AB$3,"%",""),",","."))),""))) | F8: =IF(Seguimiento!$AB$3="","",Seguimiento!$AC$3&"")
A9: =IF(Seguimiento!$A$3="","",Seguimiento!$A$3) | B9: =IF(Seguimiento!$A$3="","",Seguimiento!$B$3) | C9: =IF(Seguimiento!$A$3="","",Seguimiento!$C$3&"") | D9: 46346 | E9: =IF(Seguimiento!$AD$3="","",IF(ISNUMBER(Seguimiento!$AD$3),IF(Seguimiento!$AD$3<=1,Seguimiento!$AD$3*100,Seguimiento!$AD$3),IFERROR(IF(VALUE(SUBSTITUTE(SUBSTITUTE(Seguimiento!$AD$3,"%",""),",","."))<=1,VALUE(SUBSTITUTE(SUBSTITUTE(Seguimiento!$AD$3,"%",""),",","."))*100,VALUE(SUBSTITUTE(SUBSTITUTE(Seguimiento!$AD$3,"%",""),",","."))),""))) | F9: =IF(Seguimiento!$AD$3="","",Seguimiento!$AE$3&"")
A10: =IF(Seguimiento!$A$3="","",Seguimiento!$A$3) | B10: =IF(Seguimiento!$A$3="","",Seguimiento!$B$3) | C10: =IF(Seguimiento!$A$3="","",Seguimiento!$C$3&"") | D10: 46353 | E10: =IF(Seguimiento!$AF$3="","",IF(ISNUMBER(Seguimiento!$AF$3),IF(Seguimiento!$AF$3<=1,Seguimiento!$AF$3*100,Seguimiento!$AF$3),IFERROR(IF(VALUE(SUBSTITUTE(SUBSTITUTE(Seguimiento!$AF$3,"%",""),",","."))<=1,VALUE(SUBSTITUTE(SUBSTITUTE(Seguimiento!$AF$3,"%",""),",","."))*100,VALUE(SUBSTITUTE(SUBSTITUTE(Seguimiento!$AF$3,"%",""),",","."))),""))) | F10: =IF(Seguimiento!$AF$3="","",Seguimiento!$AG$3&"")
A11: =IF(Seguimiento!$A$3="","",Seguimiento!$A$3) | B11: =IF(Seguimiento!$A$3="","",Seguimiento!$B$3) | C11: =IF(Seguimiento!$A$3="","",Seguimiento!$C$3&"") | D11: 46360 | E11: =IF(Seguimiento!$AH$3="","",IF(ISNUMBER(Seguimiento!$AH$3),IF(Seguimiento!$AH$3<=1,Seguimiento!$AH$3*100,Seguimiento!$AH$3),IFERROR(IF(VALUE(SUBSTITUTE(SUBSTITUTE(Seguimiento!$AH$3,"%",""),",","."))<=1,VALUE(SUBSTITUTE(SUBSTITUTE(Seguimiento!$AH$3,"%",""),",","."))*100,VALUE(SUBSTITUTE(SUBSTITUTE(Seguimiento!$AH$3,"%",""),",","."))),""))) | F11: =IF(Seguimiento!$AH$3="","",Seguimiento!$AI$3&"")
